Workbook

Sheet Summary
A1: Order Dataset - Descriptive Statistics & Key Findings
A2: Source: Assignment_Week_2_project.xlsx | 1,200 orders, Jan 2023 - Jun 2025 | All figures below are live formulas on the Data sheet
A4: Metric | B4: Total Price | C4: Unit Price | D4: Quantity | E4: Items in Cart
A5: Count | B5: =COUNT(Data!$N$2:$N$1201) -> 1200 | C5: =COUNT(Data!$F$2:$F$1201) -> 1200 | D5: =COUNT(Data!$E$2:$E$1201) -> 1200 | E5: =COUNT(Data!$K$2:$K$1201) -> 1200
A6: Mean | B6: =AVERAGE(Data!$N$2:$N$1201) -> 1053.9683 | C6: =AVERAGE(Data!$F$2:$F$1201) -> 356.41275 | D6: =AVERAGE(Data!$E$2:$E$1201) -> 2.9458333 | E6: =AVERAGE(Data!$K$2:$K$1201) -> 5.485
A7: Median | B7: =MEDIAN(Data!$N$2:$N$1201) -> 823.615 | C7: =MEDIAN(Data!$F$2:$F$1201) -> 364.21 | D7: =MEDIAN(Data!$E$2:$E$1201) -> 3 | E7: =MEDIAN(Data!$K$2:$K$1201) -> 5
A8: Std Dev | B8: =STDEV(Data!$N$2:$N$1201) -> 819.85656 | C8: =STDEV(Data!$F$2:$F$1201) -> 197.17715 | D8: =STDEV(Data!$E$2:$E$1201) -> 1.4075571 | E8: =STDEV(Data!$K$2:$K$1201) -> 2.2819833
A9: Min | B9: =MIN(Data!$N$2:$N$1201) -> 11.39 | C9: =MIN(Data!$F$2:$F$1201) -> 11.39 | D9: =MIN(Data!$E$2:$E$1201) -> 1 | E9: =MIN(Data!$K$2:$K$1201) -> 1
A10: Max | B10: =MAX(Data!$N$2:$N$1201) -> 3456.4 | C10: =MAX(Data!$F$2:$F$1201) -> 699.93 | D10: =MAX(Data!$E$2:$E$1201) -> 5 | E10: =MAX(Data!$K$2:$K$1201) -> 10
A11: Skewness | B11: =SKEW(Data!$N$2:$N$1201) -> 0.89135908 | C11: =SKEW(Data!$F$2:$F$1201) -> -0.026511641 | D11: =SKEW(Data!$E$2:$E$1201) -> 0.027922314 | E11: =SKEW(Data!$K$2:$K$1201) -> 0.00087679985
A12: Note: currency columns (Total/Unit Price) are in $; Quantity and Items in Cart are unit counts.
A13: Outlier test (Total Price, IQR method) | B13: Value
A14: Q1 (25th percentile) | B14: =QUARTILE(Data!$N$2:$N$1201,1) -> 410.52
A15: Q3 (75th percentile) | B15: =QUARTILE(Data!$N$2:$N$1201,3) -> 1578.475
A16: IQR | B16: =B15-B14 -> 1167.955
A17: Upper fence (Q3 + 1.5 x IQR) | B17: =B15+1.5*B16 -> 3330.4075 | C17: =B17 -> 3330.4075
A18: Lower fence (Q1 - 1.5 x IQR) | B18: =B14-1.5*B16 -> -1341.4125
A19: Orders above upper fence | B19: =COUNTIF(Data!$N$2:$N$1201,">"&B17) -> 8
A20: Share of all orders | B20: =B19/B5 -> 0.0066666667
A22: Headline figures | B22: Value
A23: Gross revenue | B23: =SUM(Data!$N$2:$N$1201) -> 1264762
A24: Revenue from Cancelled + Returned | B24: =SUMIFS(Data!$N$2:$N$1201,Data!$I$2:$I$1201,"Cancelled")+SUMIFS(Data!$N$2:$N$1201,Data!$I$2:$I$1201,"Returned") -> 519673.91
A25: Net revenue (excl. Cancelled/Returned) | B25: =B23-B24 -> 745088.05
A26: Net as % of gross | B26: =B25/B23 -> 0.58911327
A27: Cancelled + Returned orders | B27: =COUNTIF(Data!$I$2:$I$1201,"Cancelled")+COUNTIF(Data!$I$2:$I$1201,"Returned") -> 497
A28: % of orders Cancelled/Returned | B28: =B27/B5 -> 0.41416667
A29: Unique customers | B29: =SUMPRODUCT(1/COUNTIF(Data!$C$2:$C$1201,Data!$C$2:$C$1201)) -> 1189
A30: Orders with no coupon | B30: =COUNTIF(Data!$R$2:$R$1201,"None") -> 309
A31: Top-10% orders: share of revenue | B31: =SUMIF(Data!$N$2:$N$1201,">="&PERCENTILE(Data!$N$2:$N$1201,0.9))/B23 -> 0.26264756
A33: Key observations
A34: 1. Revenue is declining ~10% per year on a like-for-like Jan-Jun basis; the drop is driven mainly by lower average order value, with order counts down only modestly (see Trends).
A35: 2. About 41% of orders and value are Cancelled or Returned; net revenue is roughly 59% of gross. This is the largest issue in the data.
A36: 3. Order value is driven by unit price and quantity. Product type, coupon, payment method and referral source show no material difference in average order value (see Segments).
A37: 4. Only 8 orders (0.7%) breach the IQR upper fence; all are Quantity 5 at unit price above $665. They are valid large orders, not errors. No outliers by z-score.
A38: 5. No true seasonality: Jan-Jun looks stronger only because it appears in 3 years vs 2 for Jul-Dec. Orders per year are ~240 in each half.
A39: 6. Data-quality flags: TotalPrice equals Quantity x UnitPrice on every row (coupon discounts not reflected); every order has a tracking number, even Cancelled/Pending; status split is near-uniform, which looks synthetic.

Sheet Trends
A1: Trends Over Time
A2: H1 = Jan 1 - Jun 30 (the only period available in all three years, so the fair like-for-like comparison)
A4: Year (H1) | B4: Orders | C4: Revenue ($) | D4: Avg Order Value ($) | E4: Orders YoY | F4: Revenue YoY | G4: AOV YoY
A5: 2023 | B5: =COUNTIFS(Data!$B$2:$B$1201,">="&DATE(A5,1,1),Data!$B$2:$B$1201,"<="&DATE(A5,6,30)) -> 252 | C5: =SUMIFS(Data!$N$2:$N$1201,Data!$B$2:$B$1201,">="&DATE(A5,1,1),Data!$B$2:$B$1201,"<="&DATE(A5,6,30)) -> 286501.52 | D5: =C5/B5 -> 1136.9108 | E5: n/a | F5: n/a | G5: n/a
A6: 2024 | B6: =COUNTIFS(Data!$B$2:$B$1201,">="&DATE(A6,1,1),Data!$B$2:$B$1201,"<="&DATE(A6,6,30)) -> 237 | C6: =SUMIFS(Data!$N$2:$N$1201,Data!$B$2:$B$1201,">="&DATE(A6,1,1),Data!$B$2:$B$1201,"<="&DATE(A6,6,30)) -> 257059.34 | D6: =C6/B6 -> 1084.6386 | E6: =B6/B5-1 -> -0.05952381 | F6: =C6/C5-1 -> -0.10276448 | G6: =D6/D5-1 -> -0.045977423
A7: 2025 | B7: =COUNTIFS(Data!$B$2:$B$1201,">="&DATE(A7,1,1),Data!$B$2:$B$1201,"<="&DATE(A7,6,30)) -> 231 | C7: =SUMIFS(Data!$N$2:$N$1201,Data!$B$2:$B$1201,">="&DATE(A7,1,1),Data!$B$2:$B$1201,"<="&DATE(A7,6,30)) -> 231882.85 | D7: =C7/B7 -> 1003.8219 | E7: =B7/B6-1 -> -0.025316456 | F7: =C7/C6-1 -> -0.097940382 | G7: =D7/D6-1 -> -0.074510262
A10: Half-year check | B10: Orders | C10: Orders per year
A11: Jan-Jun (3 years of data) | B11: =COUNTIFS(Data!$B$2:$B$1201,">="&DATE(2023,1,1),Data!$B$2:$B$1201,"<="&DATE(2023,6,30))+B6+B7 -> 720 | C11: =B11/3 -> 240
A12: Jul-Dec (2 years of data) | B12: =COUNT(Data!$B$2:$B$1201)-B11 -> 480 | C12: =B12/2 -> 240
A13: Orders per year are equal in both halves, so there is no seasonality; the raw Jan-Jun lead is a coverage artifact.
A15: Month | B15: Orders | C15: Revenue ($) | D15: Avg Order Value ($)
A16: 44927 | B16: =COUNTIFS(Data!$P$2:$P$1201,A16) -> 47 | C16: =SUMIFS(Data!$N$2:$N$1201,Data!$P$2:$P$1201,A16) -> 56685.75 | D16: =IF(B16=0,0,C16/B16) -> 1206.0798
A17: 44958 | B17: =COUNTIFS(Data!$P$2:$P$1201,A17) -> 37 | C17: =SUMIFS(Data!$N$2:$N$1201,Data!$P$2:$P$1201,A17) -> 40117.66 | D17: =IF(B17=0,0,C17/B17) -> 1084.2611
A18: 44986 | B18: =COUNTIFS(Data!$P$2:$P$1201,A18) -> 43 | C18: =SUMIFS(Data!$N$2:$N$1201,Data!$P$2:$P$1201,A18) -> 48609.37 | D18: =IF(B18=0,0,C18/B18) -> 1130.4505
A19: 45017 | B19: =COUNTIFS(Data!$P$2:$P$1201,A19) -> 31 | C19: =SUMIFS(Data!$N$2:$N$1201,Data!$P$2:$P$1201,A19) -> 27751.71 | D19: =IF(B19=0,0,C19/B19) -> 895.21645
A20: 45047 | B20: =COUNTIFS(Data!$P$2:$P$1201,A20) -> 49 | C20: =SUMIFS(Data!$N$2:$N$1201,Data!$P$2:$P$1201,A20) -> 63836.84 | D20: =IF(B20=0,0,C20/B20) -> 1302.7927
A21: 45078 | B21: =COUNTIFS(Data!$P$2:$P$1201,A21) -> 45 | C21: =SUMIFS(Data!$N$2:$N$1201,Data!$P$2:$P$1201,A21) -> 49500.19 | D21: =IF(B21=0,0,C21/B21) -> 1100.0042
A22: 45108 | B22: =COUNTIFS(Data!$P$2:$P$1201,A22) -> 44 | C22: =SUMIFS(Data!$N$2:$N$1201,Data!$P$2:$P$1201,A22) -> 42820.66 | D22: =IF(B22=0,0,C22/B22) -> 973.19682
A23: 45139 | B23: =COUNTIFS(Data!$P$2:$P$1201,A23) -> 51 | C23: =SUMIFS(Data!$N$2:$N$1201,Data!$P$2:$P$1201,A23) -> 54352.14 | D23: =IF(B23=0,0,C23/B23) -> 1065.7282
A24: 45170 | B24: =COUNTIFS(Data!$P$2:$P$1201,A24) -> 29 | C24: =SUMIFS(Data!$N$2:$N$1201,Data!$P$2:$P$1201,A24) -> 29526.67 | D24: =IF(B24=0,0,C24/B24) -> 1018.161
A25: 45200 | B25: =COUNTIFS(Data!$P$2:$P$1201,A25) -> 47 | C25: =SUMIFS(Data!$N$2:$N$1201,Data!$P$2:$P$1201,A25) -> 52607.85 | D25: =IF(B25=0,0,C25/B25) -> 1119.316
A26: 45231 | B26: =COUNTIFS(Data!$P$2:$P$1201,A26) -> 41 | C26: =SUMIFS(Data!$N$2:$N$1201,Data!$P$2:$P$1201,A26) -> 43079.67 | D26: =IF(B26=0,0,C26/B26) -> 1050.7237
A27: 45261 | B27: =COUNTIFS(Data!$P$2:$P$1201,A27) -> 46 | C27: =SUMIFS(Data!$N$2:$N$1201,Data!$P$2:$P$1201,A27) -> 43754.73 | D27: =IF(B27=0,0,C27/B27) -> 951.18978
... A45: 45809 | B45: =COUNTIFS(Data!$P$2:$P$1201,A45) -> 49 | C45: =SUMIFS(Data!$N$2:$N$1201,Data!$P$2:$P$1201,A45) -> 53047.4 | D45: =IF(B45=0,0,C45/B45) -> 1082.6

Sheet Segments
A1: Segment Breakdown
A2: Counts, revenue and average order value by category (formulas on Data sheet)
A4: Product | B4: Orders | C4: Revenue ($) | D4: Avg Order Value ($) | E4: % of Revenue
A5: Chair | B5: =COUNTIF(Data!$D$2:$D$1201,A5) -> 178 | C5: =SUMIFS(Data!$N$2:$N$1201,Data!$D$2:$D$1201,A5) -> 195620.11 | D5: =C5/B5 -> 1098.9894 | E5: =C5/SUM(Data!$N$2:$N$1201) -> 0.15466951
A6: Printer | B6: =COUNTIF(Data!$D$2:$D$1201,A6) -> 181 | C6: =SUMIFS(Data!$N$2:$N$1201,Data!$D$2:$D$1201,A6) -> 195612.61 | D6: =C6/B6 -> 1080.7327 | E6: =C6/SUM(Data!$N$2:$N$1201) -> 0.15466358
A7: Laptop | B7: =COUNTIF(Data!$D$2:$D$1201,A7) -> 173 | C7: =SUMIFS(Data!$N$2:$N$1201,Data!$D$2:$D$1201,A7) -> 192126.56 | D7: =C7/B7 -> 1110.5582 | E7: =C7/SUM(Data!$N$2:$N$1201) -> 0.15190729
A8: Tablet | B8: =COUNTIF(Data!$D$2:$D$1201,A8) -> 179 | C8: =SUMIFS(Data!$N$2:$N$1201,Data!$D$2:$D$1201,A8) -> 186568.95 | D8: =C8/B8 -> 1042.2846 | E8: =C8/SUM(Data!$N$2:$N$1201) -> 0.14751309
A9: Monitor | B9: =COUNTIF(Data!$D$2:$D$1201,A9) -> 163 | C9: =SUMIFS(Data!$N$2:$N$1201,Data!$D$2:$D$1201,A9) -> 175651.41 | D9: =C9/B9 -> 1077.616 | E9: =C9/SUM(Data!$N$2:$N$1201) -> 0.138881
A10: Desk | B10: =COUNTIF(Data!$D$2:$D$1201,A10) -> 170 | C10: =SUMIFS(Data!$N$2:$N$1201,Data!$D$2:$D$1201,A10) -> 167459.93 | D10: =C10/B10 -> 985.05841 | E10: =C10/SUM(Data!$N$2:$N$1201) -> 0.13240431
A11: Phone | B11: =COUNTIF(Data!$D$2:$D$1201,A11) -> 156 | C11: =SUMIFS(Data!$N$2:$N$1201,Data!$D$2:$D$1201,A11) -> 151722.39 | D11: =C11/B11 -> 972.57942 | E11: =C11/SUM(Data!$N$2:$N$1201) -> 0.11996122
A13: Order Status | B13: Orders | C13: Revenue ($) | D13: Avg Order Value ($) | E13: % of Revenue
A14: Delivered | B14: =COUNTIF(Data!$I$2:$I$1201,A14) -> 231 | C14: =SUMIFS(Data!$N$2:$N$1201,Data!$I$2:$I$1201,A14) -> 242600.32 | D14: =C14/B14 -> 1050.2178 | E14: =C14/SUM(Data!$N$2:$N$1201) -> 0.191815
A15: Shipped | B15: =COUNTIF(Data!$I$2:$I$1201,A15) -> 235 | C15: =SUMIFS(Data!$N$2:$N$1201,Data!$I$2:$I$1201,A15) -> 246159.58 | D15: =C15/B15 -> 1047.4876 | E15: =C15/SUM(Data!$N$2:$N$1201) -> 0.19462918
A16: Pending | B16: =COUNTIF(Data!$I$2:$I$1201,A16) -> 237 | C16: =SUMIFS(Data!$N$2:$N$1201,Data!$I$2:$I$1201,A16) -> 256328.15 | D16: =C16/B16 -> 1081.5534 | E16: =C16/SUM(Data!$N$2:$N$1201) -> 0.20266909
A17: Returned | B17: =COUNTIF(Data!$I$2:$I$1201,A17) -> 247 | C17: =SUMIFS(Data!$N$2:$N$1201,Data!$I$2:$I$1201,A17) -> 243277.7 | D17: =C17/B17 -> 984.92996 | E17: =C17/SUM(Data!$N$2:$N$1201) -> 0.19235058
A18: Cancelled | B18: =COUNTIF(Data!$I$2:$I$1201,A18) -> 250 | C18: =SUMIFS(Data!$N$2:$N$1201,Data!$I$2:$I$1201,A18) -> 276396.21 | D18: =C18/B18 -> 1105.5848 | E18: =C18/SUM(Data!$N$2:$N$1201) -> 0.21853615
A20: Payment Method | B20: Orders | C20: Revenue ($) | D20: Avg Order Value ($) | E20: % of Revenue
A21: Cash | B21: =COUNTIF(Data!$H$2:$H$1201,A21) -> 246 | C21: =SUMIFS(Data!$N$2:$N$1201,Data!$H$2:$H$1201,A21) -> 259786.29 | D21: =C21/B21 -> 1056.0418 | E21: =C21/SUM(Data!$N$2:$N$1201) -> 0.20540331
A22: Credit Card | B22: =COUNTIF(Data!$H$2:$H$1201,A22) -> 234 | C22: =SUMIFS(Data!$N$2:$N$1201,Data!$H$2:$H$1201,A22) -> 263847.63 | D22: =C22/B22 -> 1127.554 | E22: =C22/SUM(Data!$N$2:$N$1201) -> 0.20861446
A23: Debit Card | B23: =COUNTIF(Data!$H$2:$H$1201,A23) -> 232 | C23: =SUMIFS(Data!$N$2:$N$1201,Data!$H$2:$H$1201,A23) -> 232361.18 | D23: =C23/B23 -> 1001.5568 | E23: =C23/SUM(Data!$N$2:$N$1201) -> 0.1837193
A24: Gift Card | B24: =COUNTIF(Data!$H$2:$H$1201,A24) -> 230 | C24: =SUMIFS(Data!$N$2:$N$1201,Data!$H$2:$H$1201,A24) -> 246323.92 | D24: =C24/B24 -> 1070.9736 | E24: =C24/SUM(Data!$N$2:$N$1201) -> 0.19475911
A25: Online | B25: =COUNTIF(Data!$H$2:$H$1201,A25) -> 258 | C25: =SUMIFS(Data!$N$2:$N$1201,Data!$H$2:$H$1201,A25) -> 262442.94 | D25: =C25/B25 -> 1017.2207 | E25: =C25/SUM(Data!$N$2:$N$1201) -> 0.20750382
A27: Coupon Code | B27: Orders | C27: Revenue ($) | D27: Avg Order Value ($) | E27: % of Revenue
A28: None | B28: =COUNTIF(Data!$R$2:$R$1201,A28) -> 309 | C28: =SUMIFS(Data!$N$2:$N$1201,Data!$R$2:$R$1201,A28) -> 322401.41 | D28: =C28/B28 -> 1043.3703 | E28: =C28/SUM(Data!$N$2:$N$1201) -> 0.25491074
A29: FREESHIP | B29: =COUNTIF(Data!$R$2:$R$1201,A29) -> 313 | C29: =SUMIFS(Data!$N$2:$N$1201,Data!$R$2:$R$1201,A29) -> 335036.99 | D29: =C29/B29 -> 1070.4057 | E29: =C29/SUM(Data!$N$2:$N$1201) -> 0.26490122
A30: SAVE10 | B30: =COUNTIF(Data!$R$2:$R$1201,A30) -> 286 | C30: =SUMIFS(Data!$N$2:$N$1201,Data!$R$2:$R$1201,A30) -> 304840.02 | D30: =C30/B30 -> 1065.8742 | E30: =C30/SUM(Data!$N$2:$N$1201) -> 0.24102561
A31: WINTER15 | B31: =COUNTIF(Data!$R$2:$R$1201,A31) -> 292 | C31: =SUMIFS(Data!$N$2:$N$1201,Data!$R$2:$R$1201,A31) -> 302483.54 | D31: =C31/B31 -> 1035.9025 | E31: =C31/SUM(Data!$N$2:$N$1201) -> 0.23916243
A33: Referral Source | B33: Orders | C33: Revenue ($) | D33: Avg Order Value ($) | E33: % of Revenue
A34: Email | B34: =COUNTIF(Data!$M$2:$M$1201,A34) -> 250 | C34: =SUMIFS(Data!$N$2:$N$1201,Data!$M$2:$M$1201,A34) -> 261808.55 | D34: =C34/B34 -> 1047.2342 | E34: =C34/SUM(Data!$N$2:$N$1201) -> 0.20700223
A35: Facebook | B35: =COUNTIF(Data!$M$2:$M$1201,A35) -> 228 | C35: =SUMIFS(Data!$N$2:$N$1201,Data!$M$2:$M$1201,A35) -> 250410.9 | D35: =C35/B35 -> 1098.2934 | E35: =C35/SUM(Data!$N$2:$N$1201) -> 0.19799054
A36: Google | B36: =COUNTIF(Data!$M$2:$M$1201,A36) -> 241 | C36: =SUMIFS(Data!$N$2:$N$1201,Data!$M$2:$M$1201,A36) -> 250441.48 | D36: =C36/B36 -> 1039.1763 | E36: =C36/SUM(Data!$N$2:$N$1201) -> 0.19801472
A37: Instagram | B37: =COUNTIF(Data!$M$2:$M$1201,A37) -> 259 | C37: =SUMIFS(Data!$N$2:$N$1201,Data!$M$2:$M$1201,A37) -> 275285.45 | D37: =C37/B37 -> 1062.8782 | E37: =C37/SUM(Data!$N$2:$N$1201) -> 0.21765791
A38: Referral | B38: =COUNTIF(Data!$M$2:$M$1201,A38) -> 222 | C38: =SUMIFS(Data!$N$2:$N$1201,Data!$M$2:$M$1201,A38) -> 226815.58 | D38: =C38/B38 -> 1021.6918 | E38: =C38/SUM(Data!$N$2:$N$1201) -> 0.1793346

Sheet Outliers
A1: Total Price Outliers (IQR method)
A2: Static extract of orders above the upper fence on Summary!B17; the count on Summary!B19 is live and will differ if data changes
A4: OrderID | B4: Date | C4: Product | D4: Quantity | E4: Unit Price | F4: Total Price | G4: Order Status
A5: ORD200789 | B5: 45155 | C5: Tablet | D5: 5 | E5: 691.28 | F5: 3456.4 | G5: Delivered
A6: ORD201122 | B6: 45084 | C6: Monitor | D6: 5 | E6: 678.19 | F6: 3390.95 | G6: Returned
A7: ORD200632 | B7: 45048 | C7: Laptop | D7: 5 | E7: 678.16 | F7: 3390.8 | G7: Delivered
A8: ORD200469 | B8: 45256 | C8: Chair | D8: 5 | E8: 676.98 | F8: 3384.9 | G8: Cancelled
A9: ORD200328 | B9: 44985 | C9: Tablet | D9: 5 | E9: 674.04 | F9: 3370.2 | G9: Cancelled
A10: ORD200107 | B10: 45012 | C10: Printer | D10: 5 | E10: 670.75 | F10: 3353.75 | G10: Shipped
A11: ORD200326 | B11: 45474 | C11: Laptop | D11: 5 | E11: 670.48 | F11: 3352.4 | G11: Returned
A12: ORD201065 | B12: 45229 | C12: Printer | D12: 5 | E12: 666.8 | F12: 3334 | G12: Delivered
A14: All outliers are Quantity 5 at unit prices above $665: legitimate large orders rather than data errors.

Sheet Data
A1: OrderID | B1: Date | C1: CustomerID | D1: Product | E1: Quantity | F1: UnitPrice | G1: ShippingAddress | H1: PaymentMethod | I1: OrderStatus | J1: TrackingNumber | K1: ItemsInCart | L1: CouponCode | M1: ReferralSource | N1: TotalPrice | O1: Year | P1: Month | Q1: OutlierFlag | R1: CouponClean
A2: ORD200000 | B2: 44930 | C2: C72649 | D2: Monitor | E2: 5 | F2: 570.62 | G2: 928 Main St | H2: Debit Card | I2: Shipped | J2: TRK37947903 | K2: 7 | L2: SAVE10 | M2: Instagram | N2: 2853.1 | O2: =YEAR(B2) -> 2023 | P2: =DATE(YEAR(B2),MONTH(B2),1) -> 44927 | Q2: =IF(N2>Summary!$C$17,"Outlier","") | R2: =IF(L2="","None",L2) -> SAVE10
A3: ORD200001 | B3: 45527 | C3: C75739 | D3: Phone | E3: 2 | F3: 151.35 | G3: 823 Main St | H3: Online | I3: Shipped | J3: TRK91186779 | K3: 3 | L3: SAVE10 | M3: Referral | N3: 302.7 | O3: =YEAR(B3) -> 2024 | P3: =DATE(YEAR(B3),MONTH(B3),1) -> 45505 | Q3: =IF(N3>Summary!$C$17,"Outlier","") | R3: =IF(L3="","None",L3) -> SAVE10
A4: ORD200002 | B4: 45349 | C4: C81728 | D4: Tablet | E4: 5 | F4: 550.68 | G4: 512 Main St | H4: Credit Card | I4: Cancelled | J4: TRK42903982 | K4: 8 | L4: FREESHIP | M4: Email | N4: 2753.4 | O4: =YEAR(B4) -> 2024 | P4: =DATE(YEAR(B4),MONTH(B4),1) -> 45323 | Q4: =IF(N4>Summary!$C$17,"Outlier","") | R4: =IF(L4="","None",L4) -> FREESHIP
A5: ORD200003 | B5: 45214 | C5: C33540 | D5: Chair | E5: 1 | F5: 273.19 | G5: 275 Main St | H5: Debit Card | I5: Returned | J5: TRK62788070 | K5: 5 | L5: SAVE10 | M5: Facebook | N5: 273.19 | O5: =YEAR(B5) -> 2023 | P5: =DATE(YEAR(B5),MONTH(B5),1) -> 45200 | Q5: =IF(N5>Summary!$C$17,"Outlier","") | R5: =IF(L5="","None",L5) -> SAVE10
A6: ORD200004 | B6: 45785 | C6: C81840 | D6: Printer | E6: 4 | F6: 626.01 | G6: 668 Main St | H6: Online | I6: Delivered | J6: TRK29241424 | K6: 8 | L6: SAVE10 | M6: Email | N6: 2504.04 | O6: =YEAR(B6) -> 2025 | P6: =DATE(YEAR(B6),MONTH(B6),1) -> 45778 | Q6: =IF(N6>Summary!$C$17,"Outlier","") | R6: =IF(L6="","None",L6) -> SAVE10
A7: ORD200005 | B7: 45222 | C7: C37249 | D7: Phone | E7: 2 | F7: 245.86 | G7: 934 Main St | H7: Credit Card | I7: Shipped | J7: TRK72976927 | K7: 4 | L7: SAVE10 | M7: Instagram | N7: 491.72 | O7: =YEAR(B7) -> 2023 | P7: =DATE(YEAR(B7),MONTH(B7),1) -> 45200 | Q7: =IF(N7>Summary!$C$17,"Outlier","") | R7: =IF(L7="","None",L7) -> SAVE10
A8: ORD200006 | B8: 45825 | C8: C83492 | D8: Laptop | E8: 1 | F8: 664.42 | G8: 986 Main St | H8: Gift Card | I8: Returned | J8: TRK96417362 | K8: 6 | L8: SAVE10 | M8: Facebook | N8: 664.42 | O8: =YEAR(B8) -> 2025 | P8: =DATE(YEAR(B8),MONTH(B8),1) -> 45809 | Q8: =IF(N8>Summary!$C$17,"Outlier","") | R8: =IF(L8="","None",L8) -> SAVE10
A9: ORD200007 | B9: 45058 | C9: C41460 | D9: Monitor | E9: 5 | F9: 149.55 | G9: 706 Main St | H9: Cash | I9: Shipped | J9: TRK78809193 | K9: 9 | L9: FREESHIP | M9: Facebook | N9: 747.75 | O9: =YEAR(B9) -> 2023 | P9: =DATE(YEAR(B9),MONTH(B9),1) -> 45047 | Q9: =IF(N9>Summary!$C$17,"Outlier","") | R9: =IF(L9="","None",L9) -> FREESHIP
A10: ORD200008 | B10: 45749 | C10: C26817 | D10: Phone | E10: 2 | F10: 134.28 | G10: 904 Main St | H10: Gift Card | I10: Cancelled | J10: TRK61042692 | K10: 2 | M10: Email | N10: 268.56 | O10: =YEAR(B10) -> 2025 | P10: =DATE(YEAR(B10),MONTH(B10),1) -> 45748 | Q10: =IF(N10>Summary!$C$17,"Outlier","") | R10: =IF(L10="","None",L10) -> None
A11: ORD200009 | B11: 45251 | C11: C31946 | D11: Desk | E11: 4 | F11: 509.38 | G11: 102 Main St | H11: Credit Card | I11: Shipped | J11: TRK33478363 | K11: 6 | L11: SAVE10 | M11: Google | N11: 2037.52 | O11: =YEAR(B11) -> 2023 | P11: =DATE(YEAR(B11),MONTH(B11),1) -> 45231 | Q11: =IF(N11>Summary!$C$17,"Outlier","") | R11: =IF(L11="","None",L11) -> SAVE10
A12: ORD200010 | B12: 45289 | C12: C43443 | D12: Tablet | E12: 5 | F12: 625.97 | G12: 333 Main St | H12: Credit Card | I12: Returned | J12: TRK98859248 | K12: 9 | L12: WINTER15 | M12: Instagram | N12: 3129.85 | O12: =YEAR(B12) -> 2023 | P12: =DATE(YEAR(B12),MONTH(B12),1) -> 45261 | Q12: =IF(N12>Summary!$C$17,"Outlier","") | R12: =IF(L12="","None",L12) -> WINTER15
A13: ORD200011 | B13: 45339 | C13: C93861 | D13: Monitor | E13: 3 | F13: 49.14 | G13: 831 Main St | H13: Online | I13: Returned | J13: TRK48234646 | K13: 7 | L13: SAVE10 | M13: Email | N13: 147.42 | O13: =YEAR(B13) -> 2024 | P13: =DATE(YEAR(B13),MONTH(B13),1) -> 45323 | Q13: =IF(N13>Summary!$C$17,"Outlier","") | R13: =IF(L13="","None",L13) -> SAVE10
A14: ORD200012 | B14: 45580 | C14: C38785 | D14: Monitor | E14: 2 | F14: 180.5 | G14: 179 Main St | H14: Debit Card | I14: Pending | J14: TRK20419991 | K14: 6 | L14: FREESHIP | M14: Referral | N14: 361 | O14: =YEAR(B14) -> 2024 | P14: =DATE(YEAR(B14),MONTH(B14),1) -> 45566 | Q14: =IF(N14>Summary!$C$17,"Outlier","") | R14: =IF(L14="","None",L14) -> FREESHIP
A15: ORD200013 | B15: 45168 | C15: C88348 | D15: Laptop | E15: 3 | F15: 201.49 | G15: 903 Main St | H15: Credit Card | I15: Returned | J15: TRK81913874 | K15: 4 | L15: FREESHIP | M15: Facebook | N15: 604.47 | O15: =YEAR(B15) -> 2023 | P15: =DATE(YEAR(B15),MONTH(B15),1) -> 45139 | Q15: =IF(N15>Summary!$C$17,"Outlier","") | R15: =IF(L15="","None",L15) -> FREESHIP
A16: ORD200014 | B16: 45012 | C16: C98474 | D16: Tablet | E16: 2 | F16: 393.33 | G16: 980 Main St | H16: Debit Card | I16: Pending | J16: TRK79186539 | K16: 3 | L16: SAVE10 | M16: Instagram | N16: 786.66 | O16: =YEAR(B16) -> 2023 | P16: =DATE(YEAR(B16),MONTH(B16),1) -> 44986 | Q16: =IF(N16>Summary!$C$17,"Outlier","") | R16: =IF(L16="","None",L16) -> SAVE10
A17: ORD200015 | B17: 45124 | C17: C39416 | D17: Printer | E17: 1 | F17: 473.96 | G17: 942 Main St | H17: Cash | I17: Delivered | J17: TRK54930938 | K17: 3 | M17: Google | N17: 473.96 | O17: =YEAR(B17) -> 2023 | P17: =DATE(YEAR(B17),MONTH(B17),1) -> 45108 | Q17: =IF(N17>Summary!$C$17,"Outlier","") | R17: =IF(L17="","None",L17) -> None
A18: ORD200016 | B18: 44950 | C18: C28976 | D18: Printer | E18: 2 | F18: 533.81 | G18: 914 Main St | H18: Credit Card | I18: Pending | J18: TRK13194259 | K18: 3 | L18: FREESHIP | M18: Email | N18: 1067.62 | O18: =YEAR(B18) -> 2023 | P18: =DATE(YEAR(B18),MONTH(B18),1) -> 44927 | Q18: =IF(N18>Summary!$C$17,"Outlier","") | R18: =IF(L18="","None",L18) -> FREESHIP
A19: ORD200017 | B19: 45353 | C19: C60672 | D19: Tablet | E19: 1 | F19: 423.4 | G19: 382 Main St | H19: Debit Card | I19: Shipped | J19: TRK11972116 | K19: 3 | M19: Referral | N19: 423.4 | O19: =YEAR(B19) -> 2024 | P19: =DATE(YEAR(B19),MONTH(B19),1) -> 45352 | Q19: =IF(N19>Summary!$C$17,"Outlier","") | R19: =IF(L19="","None",L19) -> None
A20: ORD200018 | B20: 45742 | C20: C84329 | D20: Desk | E20: 1 | F20: 431.44 | G20: 891 Main St | H20: Gift Card | I20: Pending | J20: TRK65191045 | K20: 3 | L20: SAVE10 | M20: Facebook | N20: 431.44 | O20: =YEAR(B20) -> 2025 | P20: =DATE(YEAR(B20),MONTH(B20),1) -> 45717 | Q20: =IF(N20>Summary!$C$17,"Outlier","") | R20: =IF(L20="","None",L20) -> SAVE10
A21: ORD200019 | B21: 44949 | C21: C14552 | D21: Monitor | E21: 5 | F21: 224 | G21: 273 Main St | H21: Cash | I21: Returned | J21: TRK59101365 | K21: 9 | L21: SAVE10 | M21: Google | N21: 1120 | O21: =YEAR(B21) -> 2023 | P21: =DATE(YEAR(B21),MONTH(B21),1) -> 44927 | Q21: =IF(N21>Summary!$C$17,"Outlier","") | R21: =IF(L21="","None",L21) -> SAVE10
A22: ORD200020 | B22: 45054 | C22: C54829 | D22: Chair | E22: 5 | F22: 62.51 | G22: 587 Main St | H22: Cash | I22: Pending | J22: TRK16718651 | K22: 9 | L22: WINTER15 | M22: Instagram | N22: 312.55 | O22: =YEAR(B22) -> 2023 | P22: =DATE(YEAR(B22),MONTH(B22),1) -> 45047 | Q22: =IF(N22>Summary!$C$17,"Outlier","") | R22: =IF(L22="","None",L22) -> WINTER15
A23: ORD200021 | B23: 45613 | C23: C99023 | D23: Monitor | E23: 4 | F23: 342.95 | G23: 569 Main St | H23: Cash | I23: Delivered | J23: TRK52646983 | K23: 6 | M23: Google | N23: 1371.8 | O23: =YEAR(B23) -> 2024 | P23: =DATE(YEAR(B23),MONTH(B23),1) -> 45597 | Q23: =IF(N23>Summary!$C$17,"Outlier","") | R23: =IF(L23="","None",L23) -> None
A24: ORD200022 | B24: 44955 | C24: C34416 | D24: Monitor | E24: 2 | F24: 49.62 | G24: 633 Main St | H24: Online | I24: Pending | J24: TRK75937350 | K24: 2 | L24: SAVE10 | M24: Google | N24: 99.24 | O24: =YEAR(B24) -> 2023 | P24: =DATE(YEAR(B24),MONTH(B24),1) -> 44927 | Q24: =IF(N24>Summary!$C$17,"Outlier","") | R24: =IF(L24="","None",L24) -> SAVE10
A25: ORD200023 | B25: 45756 | C25: C42372 | D25: Phone | E25: 4 | F25: 273.25 | G25: 755 Main St | H25: Debit Card | I25: Cancelled | J25: TRK36168083 | K25: 5 | L25: FREESHIP | M25: Referral | N25: 1093 | O25: =YEAR(B25) -> 2025 | P25: =DATE(YEAR(B25),MONTH(B25),1) -> 45748 | Q25: =IF(N25>Summary!$C$17,"Outlier","") | R25: =IF(L25="","None",L25) -> FREESHIP
A26: ORD200024 | B26: 45595 | C26: C17470 | D26: Laptop | E26: 2 | F26: 230.95 | G26: 956 Main St | H26: Online | I26: Delivered | J26: TRK28775057 | K26: 3 | L26: WINTER15 | M26: Referral | N26: 461.9 | O26: =YEAR(B26) -> 2024 | P26: =DATE(YEAR(B26),MONTH(B26),1) -> 45566 | Q26: =IF(N26>Summary!$C$17,"Outlier","") | R26: =IF(L26="","None",L26) -> WINTER15
A27: ORD200025 | B27: 45497 | C27: C42577 | D27: Monitor | E27: 1 | F27: 399.98 | G27: 709 Main St | H27: Debit Card | I27: Delivered | J27: TRK69423327 | K27: 3 | L27: WINTER15 | M27: Email | N27: 399.98 | O27: =YEAR(B27) -> 2024 | P27: =DATE(YEAR(B27),MONTH(B27),1) -> 45474 | Q27: =IF(N27>Summary!$C$17,"Outlier","") | R27: =IF(L27="","None",L27) -> WINTER15
A28: ORD200026 | B28: 45357 | C28: C21944 | D28: Laptop | E28: 5 | F28: 59.55 | G28: 296 Main St | H28: Online | I28: Delivered | J28: TRK80276812 | K28: 6 | M28: Referral | N28: 297.75 | O28: =YEAR(B28) -> 2024 | P28: =DATE(YEAR(B28),MONTH(B28),1) -> 45352 | Q28: =IF(N28>Summary!$C$17,"Outlier","") | R28: =IF(L28="","None",L28) -> None
A29: ORD200027 | B29: 45344 | C29: C97593 | D29: Printer | E29: 1 | F29: 472.74 | G29: 881 Main St | H29: Online | I29: Shipped | J29: TRK89117573 | K29: 6 | L29: WINTER15 | M29: Google | N29: 472.74 | O29: =YEAR(B29) -> 2024 | P29: =DATE(YEAR(B29),MONTH(B29),1) -> 45323 | Q29: =IF(N29>Summary!$C$17,"Outlier","") | R29: =IF(L29="","None",L29) -> WINTER15
A30: ORD200028 | B30: 45251 | C30: C59823 | D30: Phone | E30: 4 | F30: 160.07 | G30: 568 Main St | H30: Online | I30: Pending | J30: TRK65895539 | K30: 5 | M30: Email | N30: 640.28 | O30: =YEAR(B30) -> 2023 | P30: =DATE(YEAR(B30),MONTH(B30),1) -> 45231 | Q30: =IF(N30>Summary!$C$17,"Outlier","") | R30: =IF(L30="","None",L30) -> None
A31: ORD200029 | B31: 45555 | C31: C33260 | D31: Desk | E31: 3 | F31: 423.53 | G31: 930 Main St | H31: Credit Card | I31: Delivered | J31: TRK59744090 | K31: 6 | L31: SAVE10 | M31: Referral | N31: 1270.59 | O31: =YEAR(B31) -> 2024 | P31: =DATE(YEAR(B31),MONTH(B31),1) -> 45536 | Q31: =IF(N31>Summary!$C$17,"Outlier","") | R31: =IF(L31="","None",L31) -> SAVE10
A32: ORD200030 | B32: 45738 | C32: C44267 | D32: Monitor | E32: 2 | F32: 426.7 | G32: 895 Main St | H32: Online | I32: Pending | J32: TRK54751444 | K32: 5 | L32: SAVE10 | M32: Referral | N32: 853.4 | O32: =YEAR(B32) -> 2025 | P32: =DATE(YEAR(B32),MONTH(B32),1) -> 45717 | Q32: =IF(N32>Summary!$C$17,"Outlier","") | R32: =IF(L32="","None",L32) -> SAVE10
A33: ORD200031 | B33: 45107 | C33: C26445 | D33: Chair | E33: 3 | F33: 500.08 | G33: 996 Main St | H33: Debit Card | I33: Returned | J33: TRK31229981 | K33: 6 | M33: Facebook | N33: 1500.24 | O33: =YEAR(B33) -> 2023 | P33: =DATE(YEAR(B33),MONTH(B33),1) -> 45078 | Q33: =IF(N33>Summary!$C$17,"Outlier","") | R33: =IF(L33="","None",L33) -> None
A34: ORD200032 | B34: 45047 | C34: C12388 | D34: Tablet | E34: 5 | F34: 536.72 | G34: 830 Main St | H34: Cash | I34: Delivered | J34: TRK99261395 | K34: 10 | M34: Email | N34: 2683.6 | O34: =YEAR(B34) -> 2023 | P34: =DATE(YEAR(B34),MONTH(B34),1) -> 45047 | Q34: =IF(N34>Summary!$C$17,"Outlier","") | R34: =IF(L34="","None",L34) -> None
A35: ORD200033 | B35: 45082 | C35: C52184 | D35: Chair | E35: 1 | F35: 162.77 | G35: 912 Main St | H35: Online | I35: Cancelled | J35: TRK73312471 | K35: 4 | L35: WINTER15 | M35: Facebook | N35: 162.77 | O35: =YEAR(B35) -> 2023 | P35: =DATE(YEAR(B35),MONTH(B35),1) -> 45078 | Q35: =IF(N35>Summary!$C$17,"Outlier","") | R35: =IF(L35="","None",L35) -> WINTER15
A36: ORD200034 | B36: 44933 | C36: C67195 | D36: Chair | E36: 4 | F36: 576.52 | G36: 926 Main St | H36: Credit Card | I36: Pending | J36: TRK55467915 | K36: 5 | L36: WINTER15 | M36: Facebook | N36: 2306.08 | O36: =YEAR(B36) -> 2023 | P36: =DATE(YEAR(B36),MONTH(B36),1) -> 44927 | Q36: =IF(N36>Summary!$C$17,"Outlier","") | R36: =IF(L36="","None",L36) -> WINTER15
A37: ORD200035 | B37: 45633 | C37: C50304 | D37: Monitor | E37: 2 | F37: 465.15 | G37: 128 Main St | H37: Online | I37: Shipped | J37: TRK46850888 | K37: 2 | L37: SAVE10 | M37: Facebook | N37: 930.3 | O37: =YEAR(B37) -> 2024 | P37: =DATE(YEAR(B37),MONTH(B37),1) -> 45627 | Q37: =IF(N37>Summary!$C$17,"Outlier","") | R37: =IF(L37="","None",L37) -> SAVE10
A38: ORD200036 | B38: 45785 | C38: C59337 | D38: Laptop | E38: 2 | F38: 534.43 | G38: 465 Main St | H38: Debit Card | I38: Pending | J38: TRK50961250 | K38: 5 | M38: Facebook | N38: 1068.86 | O38: =YEAR(B38) -> 2025 | P38: =DATE(YEAR(B38),MONTH(B38),1) -> 45778 | Q38: =IF(N38>Summary!$C$17,"Outlier","") | R38: =IF(L38="","None",L38) -> None
A39: ORD200037 | B39: 45579 | C39: C10054 | D39: Laptop | E39: 2 | F39: 76.74 | G39: 409 Main St | H39: Cash | I39: Returned | J39: TRK94005261 | K39: 7 | L39: SAVE10 | M39: Instagram | N39: 153.48 | O39: =YEAR(B39) -> 2024 | P39: =DATE(YEAR(B39),MONTH(B39),1) -> 45566 | Q39: =IF(N39>Summary!$C$17,"Outlier","") | R39: =IF(L39="","None",L39) -> SAVE10
A40: ORD200038 | B40: 45645 | C40: C15924 | D40: Laptop | E40: 1 | F40: 245.89 | G40: 549 Main St | H40: Debit Card | I40: Delivered | J40: TRK14835975 | K40: 3 | L40: SAVE10 | M40: Google | N40: 245.89 | O40: =YEAR(B40) -> 2024 | P40: =DATE(YEAR(B40),MONTH(B40),1) -> 45627 | Q40: =IF(N40>Summary!$C$17,"Outlier","") | R40: =IF(L40="","None",L40) -> SAVE10
...
